2020-02-05 12:01:35,617 - kedro.pipeline.node - ERROR - Node `split_data([example_iris_data,params:example_test_data_ratio]) -> [example_test_x,example_test_y,example_train_x,example_train_y]` failed with error: 
name 'head' is not defined
2020-02-05 12:05:52,208 - kedro.pipeline.node - ERROR - Node `predict([example_model,example_test_x]) -> [example_predictions]` failed with error: 
'numpy.ndarray' object has no attribute 'head'
2020-02-05 12:07:01,201 - kedro.pipeline.node - ERROR - Node `train_model([example_train_x,example_train_y,parameters]) -> [example_model]` failed with error: 
'numpy.ndarray' object has no attribute 'head'
2020-02-05 12:38:06,994 - root - ERROR - Kedro's ipython session startup script failed:
An exception occurred when parsing config for DataSet `shuttles`:
Cannot import module when trying to load type `kedro_tutorial.io.xls_loval.ExcelLocalDataSet`.
Traceback (most recent call last):
  File "c:\users\takafumi.a.ito\appdata\local\continuum\anaconda3\lib\site-packages\kedro\io\core.py", line 395, in parse_dataset_definition
    class_obj = load_obj(class_obj, "kedro.io")
  File "c:\users\takafumi.a.ito\appdata\local\continuum\anaconda3\lib\site-packages\kedro\utils.py", line 53, in load_obj
    module_obj = importlib.import_module(obj_path)
  File "c:\users\takafumi.a.ito\appdata\local\continuum\anaconda3\lib\importlib\__init__.py", line 127, in import_module
    return _bootstrap._gcd_import(name[level:], package, level)
  File "<frozen importlib._bootstrap>", line 1006, in _gcd_import
  File "<frozen importlib._bootstrap>", line 983, in _find_and_load
  File "<frozen importlib._bootstrap>", line 965, in _find_and_load_unlocked
ModuleNotFoundError: No module named 'kedro_tutorial.io.xls_loval'

During handling of the above exception, another exception occurred:

Traceback (most recent call last):
  File "c:\users\takafumi.a.ito\appdata\local\continuum\anaconda3\lib\site-packages\kedro\io\core.py", line 143, in from_config
    config, load_version, save_version
  File "c:\users\takafumi.a.ito\appdata\local\continuum\anaconda3\lib\site-packages\kedro\io\core.py", line 398, in parse_dataset_definition
    "Cannot import module when trying to load type `{}`.".format(class_obj)
kedro.io.core.DataSetError: Cannot import module when trying to load type `kedro_tutorial.io.xls_loval.ExcelLocalDataSet`.

During handling of the above exception, another exception occurred:

Traceback (most recent call last):
  File "C:\Users\takafumi.a.ito\Desktop\Job2020\DEX\Pipeline_Experimence\pipeline_Kedro\.ipython\profile_default\startup\00-kedro-init.py", line 36, in reload_kedro
    catalog = context.catalog
  File "c:\users\takafumi.a.ito\appdata\local\continuum\anaconda3\lib\site-packages\kedro\context\context.py", line 208, in catalog
    return self._get_catalog()
  File "c:\users\takafumi.a.ito\appdata\local\continuum\anaconda3\lib\site-packages\kedro\context\context.py", line 245, in _get_catalog
    conf_catalog, conf_creds, save_version, journal, load_versions
  File "c:\users\takafumi.a.ito\appdata\local\continuum\anaconda3\lib\site-packages\kedro\context\context.py", line 269, in _create_catalog
    load_versions=load_versions,
  File "c:\users\takafumi.a.ito\appdata\local\continuum\anaconda3\lib\site-packages\kedro\io\data_catalog.py", line 272, in from_config
    ds_name, ds_config, load_versions.get(ds_name), save_version
  File "c:\users\takafumi.a.ito\appdata\local\continuum\anaconda3\lib\site-packages\kedro\io\core.py", line 148, in from_config
    "for DataSet `{}`:\n{}".format(name, str(ex))
kedro.io.core.DataSetError: An exception occurred when parsing config for DataSet `shuttles`:
Cannot import module when trying to load type `kedro_tutorial.io.xls_loval.ExcelLocalDataSet`.
2020-02-05 12:39:04,292 - root - ERROR - Kedro's ipython session startup script failed:
An exception occurred when parsing config for DataSet `shuttles`:
Cannot import module when trying to load type `kedro_tutorial.io.xls_loval.ExcelLocalDataSet`.
Traceback (most recent call last):
  File "c:\users\takafumi.a.ito\appdata\local\continuum\anaconda3\lib\site-packages\kedro\io\core.py", line 395, in parse_dataset_definition
    class_obj = load_obj(class_obj, "kedro.io")
  File "c:\users\takafumi.a.ito\appdata\local\continuum\anaconda3\lib\site-packages\kedro\utils.py", line 53, in load_obj
    module_obj = importlib.import_module(obj_path)
  File "c:\users\takafumi.a.ito\appdata\local\continuum\anaconda3\lib\importlib\__init__.py", line 127, in import_module
    return _bootstrap._gcd_import(name[level:], package, level)
  File "<frozen importlib._bootstrap>", line 1006, in _gcd_import
  File "<frozen importlib._bootstrap>", line 983, in _find_and_load
  File "<frozen importlib._bootstrap>", line 965, in _find_and_load_unlocked
ModuleNotFoundError: No module named 'kedro_tutorial.io.xls_loval'

During handling of the above exception, another exception occurred:

Traceback (most recent call last):
  File "c:\users\takafumi.a.ito\appdata\local\continuum\anaconda3\lib\site-packages\kedro\io\core.py", line 143, in from_config
    config, load_version, save_version
  File "c:\users\takafumi.a.ito\appdata\local\continuum\anaconda3\lib\site-packages\kedro\io\core.py", line 398, in parse_dataset_definition
    "Cannot import module when trying to load type `{}`.".format(class_obj)
kedro.io.core.DataSetError: Cannot import module when trying to load type `kedro_tutorial.io.xls_loval.ExcelLocalDataSet`.

During handling of the above exception, another exception occurred:

Traceback (most recent call last):
  File "C:\Users\takafumi.a.ito\Desktop\Job2020\DEX\Pipeline_Experimence\pipeline_Kedro\.ipython\profile_default\startup\00-kedro-init.py", line 36, in reload_kedro
    catalog = context.catalog
  File "c:\users\takafumi.a.ito\appdata\local\continuum\anaconda3\lib\site-packages\kedro\context\context.py", line 208, in catalog
    return self._get_catalog()
  File "c:\users\takafumi.a.ito\appdata\local\continuum\anaconda3\lib\site-packages\kedro\context\context.py", line 245, in _get_catalog
    conf_catalog, conf_creds, save_version, journal, load_versions
  File "c:\users\takafumi.a.ito\appdata\local\continuum\anaconda3\lib\site-packages\kedro\context\context.py", line 269, in _create_catalog
    load_versions=load_versions,
  File "c:\users\takafumi.a.ito\appdata\local\continuum\anaconda3\lib\site-packages\kedro\io\data_catalog.py", line 272, in from_config
    ds_name, ds_config, load_versions.get(ds_name), save_version
  File "c:\users\takafumi.a.ito\appdata\local\continuum\anaconda3\lib\site-packages\kedro\io\core.py", line 148, in from_config
    "for DataSet `{}`:\n{}".format(name, str(ex))
kedro.io.core.DataSetError: An exception occurred when parsing config for DataSet `shuttles`:
Cannot import module when trying to load type `kedro_tutorial.io.xls_loval.ExcelLocalDataSet`.
2020-02-05 17:40:34,001 - kedro.pipeline.node - ERROR - Node `AUC_ROC([X_test,regressor,y_test]) -> None` failed with error: 
multiclass format is not supported
2020-02-05 17:45:48,596 - kedro.pipeline.node - ERROR - Node `AUC_ROC([X_test,regressor,y_test]) -> None` failed with error: 
sequence too large; cannot be greater than 32
